{
 "cells": [
  {
   "cell_type": "code",
   "execution_count": 1,
   "id": "9ae6444f",
   "metadata": {},
   "outputs": [],
   "source": [
    "import pickle"
   ]
  },
  {
   "cell_type": "code",
   "execution_count": 11,
   "id": "9252f689",
   "metadata": {},
   "outputs": [
    {
     "name": "stdout",
     "output_type": "stream",
     "text": [
      "ERROR! Session/line number was not unique in database. History logging moved to new session 176\n",
      "2418\n",
      "2418\n",
      "1214\n",
      "1214\n"
     ]
    }
   ],
   "source": [
    "\n",
    "############Adjustments##############\n",
    "\n",
    "#options\n",
    "PATH = '/media/sf_SF/Stage2021/targetedQE/' \n",
    "OPTION = 'area' # area or label\n",
    "\n",
    "\n",
    "## Adjustments\n",
    "\n",
    "filename_Y_labels = 'total_y_matrix.txt'\n",
    "\n",
    "########################\n",
    "\n",
    "\n",
    "\n",
    "# load libraries\n",
    "import pandas as pd\n",
    "import os\n",
    "import random\n",
    "from PIL import Image\n",
    "import numpy as np\n",
    "\n",
    "\n",
    "#set paths\n",
    "path_data_in = PATH + 'data/input/' + 'MachineLearning/'\n",
    "path_data_out = PATH + 'data/output/' + 'MachineLearning/'\n",
    "path_data_X = path_data_in + 'X_arrays_7377/' #png's\n",
    "path_data_y = path_data_in + 'Yarrays/' #labels\n",
    "\n",
    "\n",
    "filename = path_data_y + filename_Y_labels\n",
    "\n",
    "y = pd.read_csv(filename, sep = \"\\t\")\n",
    "\n",
    "filenames_X_train = []\n",
    "filenames_X_test = []\n",
    "directory_list = os.listdir(path_data_X)\n",
    "random.shuffle(directory_list)\n",
    "os.chdir(path_data_X)\n",
    "\n",
    "i = 0\n",
    "for filename in directory_list:\n",
    "    if \".png\" in filename :\n",
    "        if i % 3 == 0: \n",
    "            filenames_X_test.append(path_data_X + filename)\n",
    "        else:\n",
    "            filenames_X_train.append(path_data_X + filename)\n",
    "        i = i + 1\n",
    "    \n",
    "def load_X_if_matched_in_y(filenames_list, y):\n",
    "    all_images_as_array=[]\n",
    "    label=[] \n",
    "    area = []   \n",
    "\n",
    "    for filename in filenames_list:\n",
    "        filename_wopath = filename.split('X_arrays_7377/')[1]\n",
    "        filename_wopath = filename_wopath.strip(\".png\")\n",
    "\n",
    "        matching_y = y[y.SampleTargetedcombination==filename_wopath]\n",
    "        if len(matching_y) == 1:\n",
    "            label.append(matching_y.iloc[0,5]) \n",
    "            area.append(matching_y.iloc[0,3])\n",
    "        \n",
    "            img=Image.open(filename)\n",
    "            np_array = np.asarray(img)\n",
    "\n",
    "            l,b,c = np_array.shape    \n",
    "            np_array = np_array.reshape(l*b*c,)   \n",
    "            all_images_as_array.append(np_array)\n",
    "\n",
    "            \n",
    "        if len(matching_y) != 1:\n",
    "            continue\n",
    "        \n",
    "    if OPTION == 'area':\n",
    "        option = area\n",
    "    else:\n",
    "        option = label       \n",
    "    return np.array(all_images_as_array), np.array(option)\n",
    "    \n",
    "X_train,y_train = load_X_if_matched_in_y(filenames_X_train, y)\n",
    "X_test, y_test = load_X_if_matched_in_y(filenames_X_test, y)\n",
    "\n",
    "print(len(y_train))\n",
    "print(len(X_train))\n",
    "print(len(y_test))\n",
    "print(len(X_test))"
   ]
  },
  {
   "cell_type": "code",
   "execution_count": 3,
   "id": "19e75120",
   "metadata": {},
   "outputs": [],
   "source": [
    "%matplotlib inline\n",
    "import numpy as np\n",
    "import pandas as pd\n",
    "import matplotlib.pyplot as plt\n",
    "\n",
    "from sklearn import linear_model\n",
    "\n",
    "from sklearn.linear_model import Ridge\n",
    "from sklearn.linear_model import Lasso\n",
    "\n",
    "from sklearn import linear_model, datasets\n",
    "from sklearn import model_selection\n",
    "from sklearn.ensemble import BaggingClassifier\n",
    "from sklearn.tree import DecisionTreeClassifier\n",
    "from sklearn.ensemble import AdaBoostClassifier\n",
    "from sklearn.ensemble import GradientBoostingClassifier\n",
    "\n",
    "from sklearn.model_selection import train_test_split\n",
    "from sklearn.metrics import classification_report\n",
    "from sklearn import preprocessing\n",
    "\n",
    "from sklearn.metrics import confusion_matrix, accuracy_score\n",
    "from sklearn.linear_model import LogisticRegression\n",
    "from sklearn.ensemble import RandomForestClassifier\n",
    "from sklearn.ensemble import RandomForestRegressor\n",
    "from sklearn import tree\n"
   ]
  },
  {
   "cell_type": "code",
   "execution_count": 6,
   "id": "e04c2c85",
   "metadata": {},
   "outputs": [
    {
     "name": "stdout",
     "output_type": "stream",
     "text": [
      "Fitting Random Forest regression on training set\n",
      "\n",
      "\n",
      "Getting Model Accuracy...\n",
      "Training Accuracy =  0.9646971625750939\n",
      "Test Accuracy =  0.8407619206192793\n"
     ]
    }
   ],
   "source": [
    "print(\"Fitting Random Forest regression on training set\")\n",
    "\n",
    "# Fitting the regression model to the dataset\n",
    "regressor = RandomForestRegressor(n_estimators=200, max_depth=200, random_state = 18)\n",
    "regressor.fit(X_train, y_train) # Using ravel() to avoid getting 'DataConversionWarning' warning message\n",
    "\n",
    "#------------------------------------------------------------------------------------------------------------------------#\n",
    "\n",
    "\n",
    "#------------------------------------------------------------------------------------------------------------------------#\n",
    "print(\"\\n\")\n",
    "print(\"Getting Model Accuracy...\")\n",
    "\n",
    "# Get regression details\n",
    "#print(\"Estimated Coefficient = \", regressor.coef_)\n",
    "#print(\"Estimated Intercept = \", regressor.intercept_)\n",
    "print(\"Training Accuracy = \", regressor.score(X_train, y_train))\n",
    "print(\"Test Accuracy = \", regressor.score(X_test, y_test))\n",
    "\n"
   ]
  },
  {
   "cell_type": "code",
   "execution_count": 10,
   "id": "011c558c",
   "metadata": {},
   "outputs": [],
   "source": [
    "import pickle"
   ]
  },
  {
   "cell_type": "code",
   "execution_count": null,
   "id": "7d2df4ea",
   "metadata": {},
   "outputs": [
    {
     "name": "stderr",
     "output_type": "stream",
     "text": [
      "ERROR:root:Internal Python error in the inspect module.\n",
      "Below is the traceback from this internal error.\n",
      "\n",
      "ERROR:root:Internal Python error in the inspect module.\n",
      "Below is the traceback from this internal error.\n",
      "\n",
      "ERROR:root:Internal Python error in the inspect module.\n",
      "Below is the traceback from this internal error.\n",
      "\n"
     ]
    },
    {
     "name": "stdout",
     "output_type": "stream",
     "text": [
      "Traceback (most recent call last):\n",
      "  File \"/home/bit/.local/lib/python3.6/site-packages/IPython/core/interactiveshell.py\", line 3343, in run_code\n",
      "    exec(code_obj, self.user_global_ns, self.user_ns)\n",
      "  File \"<ipython-input-11-32bf16aa8800>\", line 2, in <module>\n",
      "    pickle.dump(regressor, open(filename, 'wb'))\n",
      "FileNotFoundError: [Errno 2] No such file or directory: 'regressor_84.sav'\n",
      "\n",
      "During handling of the above exception, another exception occurred:\n",
      "\n",
      "Traceback (most recent call last):\n",
      "  File \"/home/bit/.local/lib/python3.6/site-packages/IPython/core/interactiveshell.py\", line 2044, in showtraceback\n",
      "    stb = value._render_traceback_()\n",
      "AttributeError: 'FileNotFoundError' object has no attribute '_render_traceback_'\n",
      "\n",
      "During handling of the above exception, another exception occurred:\n",
      "\n",
      "Traceback (most recent call last):\n",
      "  File \"/home/bit/.local/lib/python3.6/site-packages/IPython/core/ultratb.py\", line 1169, in get_records\n",
      "    return _fixed_getinnerframes(etb, number_of_lines_of_context, tb_offset)\n",
      "  File \"/home/bit/.local/lib/python3.6/site-packages/IPython/core/ultratb.py\", line 316, in wrapped\n",
      "    return f(*args, **kwargs)\n",
      "  File \"/home/bit/.local/lib/python3.6/site-packages/IPython/core/ultratb.py\", line 350, in _fixed_getinnerframes\n",
      "    records = fix_frame_records_filenames(inspect.getinnerframes(etb, context))\n",
      "  File \"/usr/lib64/python3.6/inspect.py\", line 1490, in getinnerframes\n",
      "    frameinfo = (tb.tb_frame,) + getframeinfo(tb, context)\n",
      "  File \"/usr/lib64/python3.6/inspect.py\", line 1448, in getframeinfo\n",
      "    filename = getsourcefile(frame) or getfile(frame)\n",
      "  File \"/usr/lib64/python3.6/inspect.py\", line 696, in getsourcefile\n",
      "    if getattr(getmodule(object, filename), '__loader__', None) is not None:\n",
      "  File \"/usr/lib64/python3.6/inspect.py\", line 725, in getmodule\n",
      "    file = getabsfile(object, _filename)\n",
      "  File \"/usr/lib64/python3.6/inspect.py\", line 709, in getabsfile\n",
      "    return os.path.normcase(os.path.abspath(_filename))\n",
      "  File \"/usr/lib64/python3.6/posixpath.py\", line 383, in abspath\n",
      "    cwd = os.getcwd()\n",
      "FileNotFoundError: [Errno 2] No such file or directory\n",
      "Traceback (most recent call last):\n",
      "  File \"/home/bit/.local/lib/python3.6/site-packages/IPython/core/interactiveshell.py\", line 3343, in run_code\n",
      "    exec(code_obj, self.user_global_ns, self.user_ns)\n",
      "  File \"<ipython-input-11-32bf16aa8800>\", line 2, in <module>\n",
      "    pickle.dump(regressor, open(filename, 'wb'))\n",
      "FileNotFoundError: [Errno 2] No such file or directory: 'regressor_84.sav'\n",
      "\n",
      "During handling of the above exception, another exception occurred:\n",
      "\n",
      "Traceback (most recent call last):\n",
      "  File \"/home/bit/.local/lib/python3.6/site-packages/IPython/core/interactiveshell.py\", line 2044, in showtraceback\n",
      "    stb = value._render_traceback_()\n",
      "AttributeError: 'FileNotFoundError' object has no attribute '_render_traceback_'\n",
      "\n",
      "During handling of the above exception, another exception occurred:\n",
      "\n",
      "Traceback (most recent call last):\n",
      "  File \"/home/bit/.local/lib/python3.6/site-packages/IPython/core/interactiveshell.py\", line 3263, in run_ast_nodes\n",
      "    if (await self.run_code(code, result,  async_=asy)):\n",
      "  File \"/home/bit/.local/lib/python3.6/site-packages/IPython/core/interactiveshell.py\", line 3360, in run_code\n",
      "    self.showtraceback(running_compiled_code=True)\n",
      "  File \"/home/bit/.local/lib/python3.6/site-packages/IPython/core/interactiveshell.py\", line 2047, in showtraceback\n",
      "    value, tb, tb_offset=tb_offset)\n",
      "  File \"/home/bit/.local/lib/python3.6/site-packages/IPython/core/ultratb.py\", line 1436, in structured_traceback\n",
      "    self, etype, value, tb, tb_offset, number_of_lines_of_context)\n",
      "  File \"/home/bit/.local/lib/python3.6/site-packages/IPython/core/ultratb.py\", line 1336, in structured_traceback\n",
      "    self, etype, value, tb, tb_offset, number_of_lines_of_context\n",
      "  File \"/home/bit/.local/lib/python3.6/site-packages/IPython/core/ultratb.py\", line 1193, in structured_traceback\n",
      "    tb_offset)\n",
      "  File \"/home/bit/.local/lib/python3.6/site-packages/IPython/core/ultratb.py\", line 1150, in format_exception_as_a_whole\n",
      "    last_unique, recursion_repeat = find_recursion(orig_etype, evalue, records)\n",
      "  File \"/home/bit/.local/lib/python3.6/site-packages/IPython/core/ultratb.py\", line 451, in find_recursion\n",
      "    return len(records), 0\n",
      "TypeError: object of type 'NoneType' has no len()\n",
      "\n",
      "During handling of the above exception, another exception occurred:\n",
      "\n",
      "Traceback (most recent call last):\n",
      "  File \"/home/bit/.local/lib/python3.6/site-packages/IPython/core/interactiveshell.py\", line 2044, in showtraceback\n",
      "    stb = value._render_traceback_()\n",
      "AttributeError: 'TypeError' object has no attribute '_render_traceback_'\n",
      "\n",
      "During handling of the above exception, another exception occurred:\n",
      "\n",
      "Traceback (most recent call last):\n",
      "  File \"/home/bit/.local/lib/python3.6/site-packages/IPython/core/ultratb.py\", line 1169, in get_records\n",
      "    return _fixed_getinnerframes(etb, number_of_lines_of_context, tb_offset)\n",
      "  File \"/home/bit/.local/lib/python3.6/site-packages/IPython/core/ultratb.py\", line 316, in wrapped\n",
      "    return f(*args, **kwargs)\n",
      "  File \"/home/bit/.local/lib/python3.6/site-packages/IPython/core/ultratb.py\", line 350, in _fixed_getinnerframes\n",
      "    records = fix_frame_records_filenames(inspect.getinnerframes(etb, context))\n",
      "  File \"/usr/lib64/python3.6/inspect.py\", line 1490, in getinnerframes\n",
      "    frameinfo = (tb.tb_frame,) + getframeinfo(tb, context)\n",
      "  File \"/usr/lib64/python3.6/inspect.py\", line 1448, in getframeinfo\n",
      "    filename = getsourcefile(frame) or getfile(frame)\n",
      "  File \"/usr/lib64/python3.6/inspect.py\", line 696, in getsourcefile\n",
      "    if getattr(getmodule(object, filename), '__loader__', None) is not None:\n",
      "  File \"/usr/lib64/python3.6/inspect.py\", line 725, in getmodule\n",
      "    file = getabsfile(object, _filename)\n",
      "  File \"/usr/lib64/python3.6/inspect.py\", line 709, in getabsfile\n",
      "    return os.path.normcase(os.path.abspath(_filename))\n",
      "  File \"/usr/lib64/python3.6/posixpath.py\", line 383, in abspath\n",
      "    cwd = os.getcwd()\n",
      "FileNotFoundError: [Errno 2] No such file or directory\n",
      "Traceback (most recent call last):\n",
      "  File \"/home/bit/.local/lib/python3.6/site-packages/IPython/core/interactiveshell.py\", line 3343, in run_code\n",
      "    exec(code_obj, self.user_global_ns, self.user_ns)\n",
      "  File \"<ipython-input-11-32bf16aa8800>\", line 2, in <module>\n",
      "    pickle.dump(regressor, open(filename, 'wb'))\n",
      "FileNotFoundError: [Errno 2] No such file or directory: 'regressor_84.sav'\n",
      "\n",
      "During handling of the above exception, another exception occurred:\n",
      "\n",
      "Traceback (most recent call last):\n",
      "  File \"/home/bit/.local/lib/python3.6/site-packages/IPython/core/interactiveshell.py\", line 2044, in showtraceback\n",
      "    stb = value._render_traceback_()\n",
      "AttributeError: 'FileNotFoundError' object has no attribute '_render_traceback_'\n",
      "\n",
      "During handling of the above exception, another exception occurred:\n",
      "\n",
      "Traceback (most recent call last):\n",
      "  File \"/home/bit/.local/lib/python3.6/site-packages/IPython/core/interactiveshell.py\", line 3263, in run_ast_nodes\n",
      "    if (await self.run_code(code, result,  async_=asy)):\n",
      "  File \"/home/bit/.local/lib/python3.6/site-packages/IPython/core/interactiveshell.py\", line 3360, in run_code\n",
      "    self.showtraceback(running_compiled_code=True)\n",
      "  File \"/home/bit/.local/lib/python3.6/site-packages/IPython/core/interactiveshell.py\", line 2047, in showtraceback\n",
      "    value, tb, tb_offset=tb_offset)\n",
      "  File \"/home/bit/.local/lib/python3.6/site-packages/IPython/core/ultratb.py\", line 1436, in structured_traceback\n",
      "    self, etype, value, tb, tb_offset, number_of_lines_of_context)\n",
      "  File \"/home/bit/.local/lib/python3.6/site-packages/IPython/core/ultratb.py\", line 1336, in structured_traceback\n",
      "    self, etype, value, tb, tb_offset, number_of_lines_of_context\n",
      "  File \"/home/bit/.local/lib/python3.6/site-packages/IPython/core/ultratb.py\", line 1193, in structured_traceback\n",
      "    tb_offset)\n",
      "  File \"/home/bit/.local/lib/python3.6/site-packages/IPython/core/ultratb.py\", line 1150, in format_exception_as_a_whole\n",
      "    last_unique, recursion_repeat = find_recursion(orig_etype, evalue, records)\n",
      "  File \"/home/bit/.local/lib/python3.6/site-packages/IPython/core/ultratb.py\", line 451, in find_recursion\n",
      "    return len(records), 0\n",
      "TypeError: object of type 'NoneType' has no len()\n",
      "\n",
      "During handling of the above exception, another exception occurred:\n",
      "\n",
      "Traceback (most recent call last):\n",
      "  File \"/home/bit/.local/lib/python3.6/site-packages/IPython/core/interactiveshell.py\", line 2044, in showtraceback\n",
      "    stb = value._render_traceback_()\n",
      "AttributeError: 'TypeError' object has no attribute '_render_traceback_'\n",
      "\n",
      "During handling of the above exception, another exception occurred:\n",
      "\n",
      "Traceback (most recent call last):\n",
      "  File \"/home/bit/.local/lib/python3.6/site-packages/IPython/core/interactiveshell.py\", line 2895, in _run_cell\n",
      "    return runner(coro)\n",
      "  File \"/home/bit/.local/lib/python3.6/site-packages/IPython/core/async_helpers.py\", line 68, in _pseudo_sync_runner\n",
      "    coro.send(None)\n",
      "  File \"/home/bit/.local/lib/python3.6/site-packages/IPython/core/interactiveshell.py\", line 3072, in run_cell_async\n",
      "    interactivity=interactivity, compiler=compiler, result=result)\n",
      "  File \"/home/bit/.local/lib/python3.6/site-packages/IPython/core/interactiveshell.py\", line 3282, in run_ast_nodes\n",
      "    self.showtraceback()\n",
      "  File \"/home/bit/.local/lib/python3.6/site-packages/IPython/core/interactiveshell.py\", line 2047, in showtraceback\n",
      "    value, tb, tb_offset=tb_offset)\n",
      "  File \"/home/bit/.local/lib/python3.6/site-packages/IPython/core/ultratb.py\", line 1436, in structured_traceback\n",
      "    self, etype, value, tb, tb_offset, number_of_lines_of_context)\n",
      "  File \"/home/bit/.local/lib/python3.6/site-packages/IPython/core/ultratb.py\", line 1336, in structured_traceback\n",
      "    self, etype, value, tb, tb_offset, number_of_lines_of_context\n",
      "  File \"/home/bit/.local/lib/python3.6/site-packages/IPython/core/ultratb.py\", line 1211, in structured_traceback\n",
      "    chained_exceptions_tb_offset)\n",
      "  File \"/home/bit/.local/lib/python3.6/site-packages/IPython/core/ultratb.py\", line 1150, in format_exception_as_a_whole\n",
      "    last_unique, recursion_repeat = find_recursion(orig_etype, evalue, records)\n",
      "  File \"/home/bit/.local/lib/python3.6/site-packages/IPython/core/ultratb.py\", line 451, in find_recursion\n",
      "    return len(records), 0\n",
      "TypeError: object of type 'NoneType' has no len()\n",
      "\n",
      "During handling of the above exception, another exception occurred:\n",
      "\n",
      "Traceback (most recent call last):\n",
      "  File \"/home/bit/.local/lib/python3.6/site-packages/IPython/core/interactiveshell.py\", line 2044, in showtraceback\n",
      "    stb = value._render_traceback_()\n",
      "AttributeError: 'TypeError' object has no attribute '_render_traceback_'\n",
      "\n",
      "During handling of the above exception, another exception occurred:\n",
      "\n",
      "Traceback (most recent call last):\n",
      "  File \"/home/bit/.local/lib/python3.6/site-packages/IPython/core/ultratb.py\", line 1169, in get_records\n",
      "    return _fixed_getinnerframes(etb, number_of_lines_of_context, tb_offset)\n",
      "  File \"/home/bit/.local/lib/python3.6/site-packages/IPython/core/ultratb.py\", line 316, in wrapped\n",
      "    return f(*args, **kwargs)\n",
      "  File \"/home/bit/.local/lib/python3.6/site-packages/IPython/core/ultratb.py\", line 350, in _fixed_getinnerframes\n",
      "    records = fix_frame_records_filenames(inspect.getinnerframes(etb, context))\n",
      "  File \"/usr/lib64/python3.6/inspect.py\", line 1490, in getinnerframes\n",
      "    frameinfo = (tb.tb_frame,) + getframeinfo(tb, context)\n",
      "  File \"/usr/lib64/python3.6/inspect.py\", line 1448, in getframeinfo\n",
      "    filename = getsourcefile(frame) or getfile(frame)\n",
      "  File \"/usr/lib64/python3.6/inspect.py\", line 696, in getsourcefile\n",
      "    if getattr(getmodule(object, filename), '__loader__', None) is not None:\n",
      "  File \"/usr/lib64/python3.6/inspect.py\", line 725, in getmodule\n",
      "    file = getabsfile(object, _filename)\n",
      "  File \"/usr/lib64/python3.6/inspect.py\", line 709, in getabsfile\n",
      "    return os.path.normcase(os.path.abspath(_filename))\n",
      "  File \"/usr/lib64/python3.6/posixpath.py\", line 383, in abspath\n",
      "    cwd = os.getcwd()\n",
      "FileNotFoundError: [Errno 2] No such file or directory\n"
     ]
    }
   ],
   "source": [
    "filename = 'regressor_84.sav'\n",
    "pickle.dump(regressor, open(filename, 'wb'))"
   ]
  },
  {
   "cell_type": "code",
   "execution_count": null,
   "id": "000fe46e",
   "metadata": {},
   "outputs": [],
   "source": []
  }
 ],
 "metadata": {
  "kernelspec": {
   "display_name": "Python 3",
   "language": "python",
   "name": "python3"
  },
  "language_info": {
   "codemirror_mode": {
    "name": "ipython",
    "version": 3
   },
   "file_extension": ".py",
   "mimetype": "text/x-python",
   "name": "python",
   "nbconvert_exporter": "python",
   "pygments_lexer": "ipython3",
   "version": "3.6.8"
  }
 },
 "nbformat": 4,
 "nbformat_minor": 5
}
